Workbook

Sheet Student Raw Data
A1: Timestamp | B1: Do you agree to participate in this academic survey? | C1: Q1- What is your current academic program? | D1: Q2- How frequently do you use the FIIB Saddle Gym? | E1: Q3- How long have you been using the FIIB Saddle Gym? | F1: Q4- Which gym timing do you usually prefer? | G1: T1- The FIIB Saddle Gym has adequate and well-maintained equipment for students. | H1: T2- The gym provides sufficient space for students to exercise comfortably. | I1: T3- The gym has a clean and hygienic environment. | J1: T4- The gym provides a comfortable and suitable physical environment for exercise. | K1: T5- The gym has a sufficient variety of equipment to meet students' fitness needs. | L1: R1. Gym machines and equipment are generally functioning properly when I need to use them. | M1: R2. The gym operates according to its stated timings and scheduled slots. | N1: R3. The DigiCampus booking process works reliably when I book a gym slot. | O1: R4. When I successfully book a gym slot, I am able to use the gym during that scheduled slot. | P1: RS1. The trainer is readily available when I need assistance during my workout. | Q1: RS2. The trainer responds promptly to my questions and queries. | R1: RS3. I receive timely assistance when I face a problem while using the gym. | S1: RS4. The trainer is willing to help me with my fitness-related needs. | T1: A1. The trainer has sufficient knowledge about exercise, fitness and training. | U1: A2. The trainer provides clear and correct guidance on the use of gym equipment. | V1: A3. The trainer helps me perform exercises using the correct posture and technique. | W1: A4. I feel confident about my safety when exercising under the trainer's guidance. | X1: E1. The trainer understands my individual fitness goals. | Y1: E2. The trainer provides personalized exercise guidance according to my fitness needs. | Z1: E3. The trainer considers my individual needs when recommending exercises or workout plans. | AA1: Q5- Overall, how satisfied are you with the FIIB Saddle Gym? | AB1: Q6- Overall, the FIIB Saddle Gym meets my expectations as a fitness facility. | AC1: Q7- Would you recommend the FIIB Saddle Gym to other eligible FIIB students? | AD1: Q8- What is the biggest problem or challenge you face while using the FIIB Saddle Gym? | AE1: Q9- What one improvement would most improve your experience at the FIIB Saddle Gym? | AF1: Q10- Please share any additional comments or suggestions regarding the FIIB Saddle Gym.
A2: 46276.834 | B2: Yes | C2: PGDM | D2: Less than once a week | E2: Less than 1 month | F2: No specific preference | G2: Neutral | H2: Neutral | I2: Neutral | J2: Neutral | K2: Neutral | L2: Neutral | M2: Neutral | N2: Neutral | O2: Neutral | P2: Neutral | Q2: Neutral | R2: Neutral | S2: Neutral | T2: Neutral | U2: Neutral | V2: Neutral | W2: Neutral | X2: Neutral | Y2: Neutral | Z2: Neutral | AA2: 5 | AB2: Neutral | AC2: Not Sure | AD2: Issue with space | AE2: Nothing to much | AF2: Nothing
A3: 46276.835 | B3: Yes | C3: PGDM-FM | D3: Less than once a week | E3: Less than 1 month | F3: Evening | G3: Neutral | H3: Neutral | I3: Agree | J3: Agree | K3: Neutral | L3: Agree | M3: Agree | N3: Agree | O3: Agree | P3: Strongly Agree | Q3: Agree | R3: Strongly Agree | S3: Strongly Agree | T3: Strongly Agree | U3: Strongly agree | V3: Strongly agree | W3: Agree | X3: Strongly Agree | Y3: Strongly Agree | Z3: Strongly Agree | AA3: 4 | AB3: Agree | AC3: Probably Yes | AD3: It gets very crowded during peak hours, and there is often a long wait time to use popular equipment like dumbbells, benches, or cables | AE3: Adding a few more sets of popular weights and benches would greatly improve the experience and reduce waiting | AF3: Overall, the gym is a great facility, but managing peak-hour traffic or adding a real-time crowd tracker could help.
A4: 46276.873 | B4: Yes | C4: PGDM | D4: 4-5 times a week | E4: 1–3 months | F4: Evening | G4: Agree | H4: Neutral | I4: Agree | J4: Agree | K4: Neutral | L4: Agree | M4: Agree | N4: Strongly Agree | O4: Strongly Agree | P4: Strongly Agree | Q4: Agree | R4: Strongly Agree | S4: Strongly Agree | T4: Agree | U4: Agree | V4: Agree | W4: Agree | X4: Agree | Y4: Agree | Z4: Neutral | AA4: 5 | AB4: Strongly Agree | AC4: Definitely Yes
A5: 46277.024 | B5: Yes | C5: PGDM | D5: 4-5 times a week | E5: 1–3 months | F5: Evening | G5: Strongly agree | H5: Strongly agree | I5: Strongly agree | J5: Strongly agree | K5: Strongly agree | L5: Strongly Agree | M5: Strongly Agree | N5: Strongly Agree | O5: Strongly Agree | P5: Strongly Agree | Q5: Strongly Agree | R5: Strongly Agree | S5: Strongly Agree | T5: Strongly Agree | U5: Strongly agree | V5: Strongly agree | W5: Strongly Agree | X5: Strongly Agree | Y5: Strongly Agree | Z5: Strongly Agree | AA5: 5 | AB5: Strongly Agree | AC5: Definitely Yes | AD5: Na | AE5: Na | AF5: na
A6: 46277.085 | B6: Yes | C6: PGDM | D6: Daily | E6: 1–3 months | F6: Evening | G6: Neutral | H6: Strongly agree | I6: Strongly agree | J6: Strongly agree | K6: Neutral | L6: Neutral | M6: Strongly Agree | N6: Strongly Agree | O6: Strongly Agree | P6: Strongly Agree | Q6: Strongly Agree | R6: Strongly Agree | S6: Strongly Agree | T6: Strongly Agree | U6: Strongly agree | V6: Strongly agree | W6: Strongly Agree | X6: Strongly Agree | Y6: Strongly Agree | Z6: Strongly Agree | AA6: 3 | AB6: Agree | AC6: Probably Yes | AD6: machine is not working like treadmill. | AE6: Repair treadmill or Replace to new. | AF6: add more equipment.
A7: 46277.086 | B7: Yes | C7: PGDM | D7: 2-3 times a week | E7: 1–3 months | F7: Evening | G7: Agree | H7: Agree | I7: Strongly agree | J7: Strongly agree | K7: Strongly disagree | L7: Strongly Agree | M7: Agree | N7: Strongly Agree | O7: Strongly Agree | P7: Strongly Agree | Q7: Strongly Agree | R7: Strongly Agree | S7: Strongly Agree | T7: Strongly Agree | U7: Agree | V7: Strongly agree | W7: Strongly Agree | X7: Agree | Y7: Strongly Agree | Z7: Agree | AA7: 4 | AB7: Agree | AC7: Probably Yes | AD7: Less machines variety at the gym | AE7: Install new machines for better experience | AF7: There should be more exercise machines
A8: 46277.345 | B8: Yes | C8: PGDM-FM | D8: Daily | E8: 3–6 months | F8: No specific preference | G8: Agree | H8: Agree | I8: Strongly agree | J8: Strongly agree | K8: Agree | L8: Agree | M8: Strongly Agree | N8: Disagree | O8: Neutral | P8: Strongly Agree | Q8: Strongly Agree | R8: Strongly Agree | S8: Strongly Agree | T8: Strongly Agree | U8: Strongly agree | V8: Strongly agree | W8: Strongly Agree | X8: Disagree | Y8: Strongly Agree | Z8: Strongly Agree | AA8: 5 | AB8: Strongly Agree | AC8: Definitely Yes | AE8: Please change few machines that are just taking space.
A9: 46277.39 | B9: Yes | C9: PGDM | D9: Daily | E9: More than 1 year | F9: Evening | G9: Agree | H9: Strongly disagree | I9: Strongly agree | J9: Strongly agree | K9: Agree | L9: Strongly Agree | M9: Strongly Agree | N9: Strongly Agree | O9: Strongly Agree | P9: Strongly Agree | Q9: Strongly Agree | R9: Strongly Agree | S9: Strongly Agree | T9: Strongly Agree | U9: Strongly agree | V9: Strongly agree | W9: Strongly Agree | X9: Strongly Agree | Y9: Strongly Agree | Z9: Strongly Agree | AA9: 5 | AB9: Agree | AC9: Definitely Yes | AD9: Very small as compared to other commercial gyms | AE9: Add more machines
A10: 46277.394 | B10: Yes | C10: PGDM | D10: 2-3 times a week | E10: Less than 1 month | F10: Morning | G10: Agree | H10: Agree | I10: Neutral | J10: Agree | K10: Agree | L10: Agree | M10: Agree | N10: Agree | O10: Agree | P10: Agree | Q10: Agree | R10: Neutral | S10: Strongly Agree | T10: Agree | U10: Agree | V10: Strongly agree | W10: Strongly Agree | X10: Agree | Y10: Agree | Z10: Agree | AA10: 4 | AB10: Agree | AC10: Probably Yes | AD10: Equipment and space problem | AE10: Slot bookings
A11: 46278.544 | B11: Yes | C11: PGDM | D11: 4-5 times a week | E11: 3–6 months | F11: Evening | G11: Agree | H11: Disagree | I11: Agree | J11: Agree | K11: Disagree | L11: Agree | M11: Strongly Agree | N11: Strongly Agree | O11: Strongly Agree | P11: Agree | Q11: Agree | R11: Strongly Agree | S11: Strongly Agree | T11: Agree | U11: Strongly agree | V11: Strongly agree | W11: Agree | X11: Agree | Y11: Agree | Z11: Neutral | AA11: 3 | AB11: Neutral | AC11: Not Sure | AD11: Space problem | AE11: trademill not working properly
A12: 46278.562 | B12: Yes | C12: PGDM | D12: Once a week | E12: 6–12 months | F12: No specific preference | G12: Neutral | H12: Strongly disagree | I12: Neutral | J12: Disagree | K12: Strongly disagree | L12: Agree | M12: Neutral | N12: Disagree | O12: Agree | P12: Neutral | Q12: Neutral | R12: Agree | S12: Neutral | T12: Neutral | U12: Neutral | V12: Disagree | W12: Neutral | X12: Neutral | Y12: Disagree | Z12: Neutral | AA12: 1 | AB12: Strongly Disagree | AC12: Definitely No
A13: 46278.58 | B13: Yes | C13: PGDM | D13: 2-3 times a week | E13: 1–3 months | F13: Morning | G13: Neutral | H13: Neutral | I13: Neutral | J13: Neutral | K13: Neutral | L13: Neutral | M13: Neutral | N13: Neutral | O13: Neutral | P13: Neutral | Q13: Neutral | R13: Neutral | S13: Neutral | T13: Neutral | U13: Neutral | V13: Neutral | W13: Neutral | X13: Neutral | Y13: Neutral | Z13: Neutral | AA13: 3 | AB13: Neutral | AC13: Definitely Yes
A14: 46278.586 | B14: Yes | C14: PGDM | D14: Once a week | E14: More than 1 year | F14: No specific preference | G14: Strongly agree | H14: Strongly agree | I14: Strongly agree | J14: Strongly agree | K14: Strongly agree | L14: Strongly Agree | M14: Strongly Agree | N14: Strongly Agree | O14: Strongly Agree | P14: Strongly Agree | Q14: Strongly Agree | R14: Agree | S14: Agree | T14: Agree | U14: Agree | V14: Agree | W14: Agree | X14: Agree | Y14: Agree | Z14: Agree | AA14: 5 | AB14: Agree | AC14: Probably Yes
A15: 46278.587 | B15: Yes | C15: PGDM | D15: 2-3 times a week | E15: 6–12 months | F15: Morning | G15: Neutral | H15: Agree | I15: Agree | J15: Strongly agree | K15: Agree | L15: Agree | M15: Strongly Agree | N15: Strongly Agree | O15: Strongly Agree | P15: Neutral | Q15: Disagree | R15: Neutral | S15: Disagree | T15: Strongly Agree | U15: Strongly agree | V15: Strongly agree | W15: Strongly Agree | X15: Strongly Agree | Y15: Strongly Agree | Z15: Agree | AA15: 5 | AB15: Strongly Agree | AC15: Definitely No | AD15: Less equipments | AE15: Adding more equipment’s | AF15: No
A16: 46278.588 | B16: Yes | C16: PGDM-FM | D16: Daily | E16: 6–12 months | F16: No specific preference | G16: Agree | H16: Agree | I16: Strongly agree | J16: Strongly agree | K16: Agree | L16: Strongly Agree | M16: Strongly Agree | N16: Strongly Agree | O16: Strongly Agree | P16: Agree | Q16: Strongly Agree | R16: Agree | S16: Agree | T16: Strongly Agree | U16: Strongly agree | V16: Agree | W16: Agree | X16: Strongly Agree | Y16: Agree | Z16: Agree | AA16: 2 | AB16: Neutral | AC16: Not Sure | AD16: space | AE16: more equipments
A17: 46278.592 | B17: Yes | C17: PGDM | D17: 4-5 times a week | E17: 6–12 months | F17: Evening | G17: Neutral | H17: Disagree | I17: Agree | J17: Neutral | K17: Disagree | L17: Neutral | M17: Neutral | N17: Neutral | O17: Neutral | P17: Neutral | Q17: Neutral | R17: Neutral | S17: Agree | T17: Agree | U17: Neutral | V17: Neutral | W17: Disagree | X17: Neutral | Y17: Neutral | Z17: Neutral | AA17: 2 | AB17: Disagree | AC17: Probably No
A18: 46278.593 | B18: Yes | C18: PGDM-FM | D18: Once a week | E18: More than 1 year | F18: No specific preference | G18: Strongly agree | H18: Neutral | I18: Strongly agree | J18: Agree | K18: Agree | L18: Agree | M18: Strongly Agree | N18: Agree | O18: Agree | P18: Strongly Agree | Q18: Strongly Agree | R18: Strongly Agree | S18: Strongly Agree | T18: Strongly Agree | U18: Strongly agree | V18: Strongly agree | W18: Strongly Agree | X18: Strongly Agree | Y18: Strongly Agree | Z18: Strongly Agree | AA18: 5
A19: 46278.594 | B19: Yes | C19: PGDM-FM | D19: Less than once a week | E19: More than 1 year | F19: Morning | G19: Strongly agree | H19: Agree | I19: Strongly agree | J19: Agree | K19: Strongly agree | L19: Strongly Agree | M19: Agree | N19: Strongly Agree | O19: Strongly Agree | P19: Strongly Agree | Q19: Strongly Agree | R19: Strongly Agree | S19: Strongly Agree | T19: Strongly Agree | U19: Strongly agree | V19: Strongly agree | W19: Strongly Agree | X19: Strongly Agree | Y19: Strongly Agree | Z19: Strongly Agree | AA19: 5 | AB19: Agree | AC19: Probably Yes | AF19: After working out at the gym, there should be a small shower room nearby so that students can freshen up before going to class and avoid feeling or smelling sweaty.
A20: 46278.599 | B20: Yes | C20: PGDM | D20: Less than once a week | E20: More than 1 year | F20: Evening | G20: Neutral | H20: Neutral | I20: Neutral | J20: Neutral | K20: Neutral | L20: Neutral | M20: Neutral | N20: Neutral | O20: Neutral | P20: Neutral | Q20: Neutral | R20: Neutral | S20: Neutral | T20: Neutral | U20: Neutral | V20: Neutral | W20: Neutral | X20: Neutral | Y20: Neutral | Z20: Neutral | AA20: 3 | AB20: Neutral | AC20: Not Sure | AD20: No | AE20: No | AF20: No
A21: 46278.606 | B21: Yes | C21: PGDM | D21: Less than once a week | E21: More than 1 year | F21: No specific preference | G21: Strongly agree | H21: Neutral | I21: Strongly agree | J21: Strongly agree | K21: Agree | L21: Agree | M21: Neutral | N21: Neutral | O21: Agree | P21: Strongly Agree | Q21: Strongly Agree | R21: Strongly Agree | S21: Strongly Agree | T21: Strongly Agree | U21: Strongly agree | V21: Strongly agree | W21: Strongly Agree | X21: Strongly Agree | Y21: Strongly Agree | Z21: Strongly Agree | AA21: 5 | AB21: Neutral | AC21: Probably Yes
A22: 46278.643 | B22: Yes | C22: PGDM-FM | D22: Daily | E22: 6–12 months | F22: Evening | G22: Neutral | H22: Agree | I22: Agree | J22: Strongly agree | K22: Strongly agree | L22: Strongly Agree | M22: Strongly Agree | N22: Strongly Agree | O22: Strongly Agree | P22: Strongly Agree | Q22: Strongly Agree | R22: Strongly Agree | S22: Strongly Agree | T22: Strongly Agree | U22: Strongly agree | W22: Strongly Agree | X22: Strongly Agree | Y22: Strongly Agree | Z22: Strongly Agree | AA22: 5 | AB22: Strongly Agree | AC22: Definitely Yes

Sheet Trainer Raw Data
A1: Timestamp | B1: Q1. What is your role at the FIIB Saddle Gym? | C1: Q2. How long have you been providing training/services at the FIIB Saddle Gym? | D1: T1. The FIIB Saddle Gym has adequate and well-maintained equipment for students. | E1: T2. The gym provides sufficient space for students to exercise comfortably. | F1: T3. The gym has a clean and hygienic environment. | G1: T4. The gym provides a comfortable and suitable physical environment for exercise. | H1: T5. The gym has a sufficient variety of equipment to meet students' fitness needs. | I1: R1. Gym machines and equipment are generally functioning properly when students need to use them. | J1: R2. The gym operates according to its stated timings and scheduled slots. | K1: R3. The DigiiCampus booking process works reliably for students booking gym slots. | L1: R4. Students who successfully book a gym slot are able to use the gym during their scheduled slot. | M1: RS1. The trainer is readily available when students need assistance during their workout. | N1: RS2. The trainer responds promptly to students' questions and queries. | O1: RS3. Students receive timely assistance when they face a problem while using the gym. | P1: RS4. The trainer is willing to help students with their fitness-related needs. | Q1: A1. The trainer has sufficient knowledge about exercise, fitness and training. | R1: A2. The trainer provides clear and correct guidance on the use of gym equipment. | S1: A3. The trainer helps students perform exercises using the correct posture and technique. | T1: A4. Students can feel confident about their safety when exercising under the trainer's guidance. | U1: E1. The trainer understands students' individual fitness goals. | V1: E2. The trainer provides personalized exercise guidance according to students' fitness needs. | W1: E3. The trainer considers individual needs when recommending exercises or workout plans. | X1: Q1. Overall, how would you rate the service quality of the FIIB Saddle Gym? | Y1: Q2. Overall, the FIIB Saddle Gym is able to meet students' fitness-related needs. Options: | Z1: Q1. What is the biggest challenge you face while managing the FIIB Saddle Gym? | AA1: Q2. What challenges do you face because of the gym's space or 10-student capacity? | AB1: Q3. Are there any recurring issues related to equipment availability or functioning? | AC1: Q4. What improvement would most improve students' gym experience?
A2: 46276.99 | B2: Gym Trainer | C2: More than 2 years | D2: Strongly agree | E2: Agree | F2: Strongly agree | G2: Strongly Agree | H2: Agree | I2: Strongly Agree | J2: Agree | K2: Neutral | L2: Strongly Agree | M2: Strongly Agree | N2: Strongly agree | O2: Strongly agree | P2: Strongly agree | Q2: Strongly Agree | R2: Strongly agree | S2: Strongly agree | T2: Strongly agree | U2: Strongly agree | V2: Strongly agree | W2: Strongly Agree | X2: 5 | Y2: Strongly agree | Z2: Space is less…so little challenge but manageable | AA2: Littile challenging but… I can handle well. | AC2: Need to add some equipments

Sheet Student Coded
A1: Timestamp | B1: Do you agree to participate in this academic survey? | C1: Q1- What is your current academic program? | D1: Q2- How frequently do you use the FIIB Saddle Gym? | E1: Q3- How long have you been using the FIIB Saddle Gym? | F1: Q4- Which gym timing do you usually prefer? | G1: T1- The FIIB Saddle Gym has adequate and well-maintained equipment for students. | H1: T2- The gym provides sufficient space for students to exercise comfortably. | I1: T3- The gym has a clean and hygienic environment. | J1: T4- The gym provides a comfortable and suitable physical environment for exercise. | K1: T5- The gym has a sufficient variety of equipment to meet students' fitness needs. | L1: R1. Gym machines and equipment are generally functioning properly when I need to use them. | M1: R2. The gym operates according to its stated timings and scheduled slots. | N1: R3. The DigiCampus booking process works reliably when I book a gym slot. | O1: R4. When I successfully book a gym slot, I am able to use the gym during that scheduled slot. | P1: RS1. The trainer is readily available when I need assistance during my workout. | Q1: RS2. The trainer responds promptly to my questions and queries. | R1: RS3. I receive timely assistance when I face a problem while using the gym. | S1: RS4. The trainer is willing to help me with my fitness-related needs. | T1: A1. The trainer has sufficient knowledge about exercise, fitness and training. | U1: A2. The trainer provides clear and correct guidance on the use of gym equipment. | V1: A3. The trainer helps me perform exercises using the correct posture and technique. | W1: A4. I feel confident about my safety when exercising under the trainer's guidance. | X1: E1. The trainer understands my individual fitness goals. | Y1: E2. The trainer provides personalized exercise guidance according to my fitness needs. | Z1: E3. The trainer considers my individual needs when recommending exercises or workout plans. | AA1: Q5- Overall, how satisfied are you with the FIIB Saddle Gym? | AB1: Q6- Overall, the FIIB Saddle Gym meets my expectations as a fitness facility. | AC1: Q7- Would you recommend the FIIB Saddle Gym to other eligible FIIB students? | AD1: Q8- What is the biggest problem or challenge you face while using the FIIB Saddle Gym? | AE1: Q9- What one improvement would most improve your experience at the FIIB Saddle Gym? | AF1: Q10- Please share any additional comments or suggestions regarding the FIIB Saddle Gym.
A2: ='Student Raw Data'!A2 -> 46276.834 | B2: ='Student Raw Data'!B2 -> Yes | C2: ='Student Raw Data'!C2 -> PGDM | D2: ='Student Raw Data'!D2 -> Less than once a week | E2: ='Student Raw Data'!E2 -> Less than 1 month | F2: ='Student Raw Data'!F2 -> No specific preference | G2: =IF('Student Raw Data'!G2="","",IF(OR(TRIM('Student Raw Data'!G2)="Strongly disagree",TRIM('Student Raw Data'!G2)="Strongly Disagree"),1,IF(TRIM('Student Raw Data'!G2)="Disagree",2,IF(OR(TRIM('Student Raw Data'!G2)="Neutral",TRIM('Student Raw Data'!G2)="Neither Agree nor Disagree"),3,IF(TRIM('Student Raw Data'!G2)="Agree",4,IF(OR(TRIM('Student Raw Data'!G2)="Strongly agree",TRIM('Student Raw Data'!G2)="Strongly Agree"),5,"")))))) -> 3 | H2: =IF('Student Raw Data'!H2="","",IF(OR(TRIM('Student Raw Data'!H2)="Strongly disagree",TRIM('Student Raw Data'!H2)="Strongly Disagree"),1,IF(TRIM('Student Raw Data'!H2)="Disagree",2,IF(OR(TRIM('Student Raw Data'!H2)="Neutral",TRIM('Student Raw Data'!H2)="Neither Agree nor Disagree"),3,IF(TRIM('Student Raw Data'!H2)="Agree",4,IF(OR(TRIM('Student Raw Data'!H2)="Strongly agree",TRIM('Student Raw Data'!H2)="Strongly Agree"),5,"")))))) -> 3 | I2: =IF('Student Raw Data'!I2="","",IF(OR(TRIM('Student Raw Data'!I2)="Strongly disagree",TRIM('Student Raw Data'!I2)="Strongly Disagree"),1,IF(TRIM('Student Raw Data'!I2)="Disagree",2,IF(OR(TRIM('Student Raw Data'!I2)="Neutral",TRIM('Student Raw Data'!I2)="Neither Agree nor Disagree"),3,IF(TRIM('Student Raw Data'!I2)="Agree",4,IF(OR(TRIM('Student Raw Data'!I2)="Strongly agree",TRIM('Student Raw Data'!I2)="Strongly Agree"),5,"")))))) -> 3 | J2: =IF('Student Raw Data'!J2="","",IF(OR(TRIM('Student Raw Data'!J2)="Strongly disagree",TRIM('Student Raw Data'!J2)="Strongly Disagree"),1,IF(TRIM('Student Raw Data'!J2)="Disagree",2,IF(OR(TRIM('Student Raw Data'!J2)="Neutral",TRIM('Student Raw Data'!J2)="Neither Agree nor Disagree"),3,IF(TRIM('Student Raw Data'!J2)="Agree",4,IF(OR(TRIM('Student Raw Data'!J2)="Strongly agree",TRIM('Student Raw Data'!J2)="Strongly Agree"),5,"")))))) -> 3 | K2: =IF('Student Raw Data'!K2="","",IF(OR(TRIM('Student Raw Data'!K2)="Strongly disagree",TRIM('Student Raw Data'!K2)="Strongly Disagree"),1,IF(TRIM('Student Raw Data'!K2)="Disagree",2,IF(OR(TRIM('Student Raw Data'!K2)="Neutral",TRIM('Student Raw Data'!K2)="Neither Agree nor Disagree"),3,IF(TRIM('Student Raw Data'!K2)="Agree",4,IF(OR(TRIM('Student Raw Data'!K2)="Strongly agree",TRIM('Student Raw Data'!K2)="Strongly Agree"),5,"")))))) -> 3 | L2: =IF('Student Raw Data'!L2="","",IF(OR(TRIM('Student Raw Data'!L2)="Strongly disagree",TRIM('Student Raw Data'!L2)="Strongly Disagree"),1,IF(TRIM('Student Raw Data'!L2)="Disagree",2,IF(OR(TRIM('Student Raw Data'!L2)="Neutral",TRIM('Student Raw Data'!L2)="Neither Agree nor Disagree"),3,IF(TRIM('Student Raw Data'!L2)="Agree",4,IF(OR(TRIM('Student Raw Data'!L2)="Strongly agree",TRIM('Student Raw Data'!L2)="Strongly Agree"),5,"")))))) -> 3 | M2: =IF('Student Raw Data'!M2="","",IF(OR(TRIM('Student Raw Data'!M2)="Strongly disagree",TRIM('Student Raw Data'!M2)="Strongly Disagree"),1,IF(TRIM('Student Raw Data'!M2)="Disagree",2,IF(OR(TRIM('Student Raw Data'!M2)="Neutral",TRIM('Student Raw Data'!M2)="Neither Agree nor Disagree"),3,IF(TRIM('Student Raw Data'!M2)="Agree",4,IF(OR(TRIM('Student Raw Data'!M2)="Strongly agree",TRIM('Student Raw Data'!M2)="Strongly Agree"),5,"")))))) -> 3 | N2: =IF('Student Raw Data'!N2="","",IF(OR(TRIM('Student Raw Data'!N2)="Strongly disagree",TRIM('Student Raw Data'!N2)="Strongly Disagree"),1,IF(TRIM('Student Raw Data'!N2)="Disagree",2,IF(OR(TRIM('Student Raw Data'!N2)="Neutral",TRIM('Student Raw Data'!N2)="Neither Agree nor Disagree"),3,IF(TRIM('Student Raw Data'!N2)="Agree",4,IF(OR(TRIM('Student Raw Data'!N2)="Strongly agree",TRIM('Student Raw Data'!N2)="Strongly Agree"),5,"")))))) -> 3 | ... Z2: =IF('Student Raw Data'!Z2="","",IF(OR(TRIM('Student Raw Data'!Z2)="Strongly disagree",TRIM('Student Raw Data'!Z2)="Strongly Disagree"),1,IF(TRIM('Student Raw Data'!Z2)="Disagree",2,IF(OR(TRIM('Student Raw Data'!Z2)="Neutral",TRIM('Student Raw Data'!Z2)="Neither Agree nor Disagree"),3,IF(TRIM('Student Raw Data'!Z2)="Agree",4,IF(OR(TRIM('Student Raw Data'!Z2)="Strongly agree",TRIM('Student Raw Data'!Z2)="Strongly Agree"),5,"")))))) -> 3 | AA2: ='Student Raw Data'!AA2 -> 5 | AB2: ='Student Raw Data'!AB2 -> Neutral | AC2: ='Student Raw Data'!AC2 -> Not Sure | AD2: ='Student Raw Data'!AD2 -> Issue with space | AE2: ='Student Raw Data'!AE2 -> Nothing to much | AF2: ='Student Raw Data'!AF2 -> Nothing
A3: ='Student Raw Data'!A3 -> 46276.835 | B3: ='Student Raw Data'!B3 -> Yes | C3: ='Student Raw Data'!C3 -> PGDM-FM | D3: ='Student Raw Data'!D3 -> Less than once a week | E3: ='Student Raw Data'!E3 -> Less than 1 month | F3: ='Student Raw Data'!F3 -> Evening | G3: =IF('Student Raw Data'!G3="","",IF(OR(TRIM('Student Raw Data'!G3)="Strongly disagree",TRIM('Student Raw Data'!G3)="Strongly Disagree"),1,IF(TRIM('Student Raw Data'!G3)="Disagree",2,IF(OR(TRIM('Student Raw Data'!G3)="Neutral",TRIM('Student Raw Data'!G3)="Neither Agree nor Disagree"),3,IF(TRIM('Student Raw Data'!G3)="Agree",4,IF(OR(TRIM('Student Raw Data'!G3)="Strongly agree",TRIM('Student Raw Data'!G3)="Strongly Agree"),5,"")))))) -> 3 | H3: =IF('Student Raw Data'!H3="","",IF(OR(TRIM('Student Raw Data'!H3)="Strongly disagree",TRIM('Student Raw Data'!H3)="Strongly Disagree"),1,IF(TRIM('Student Raw Data'!H3)="Disagree",2,IF(OR(TRIM('Student Raw Data'!H3)="Neutral",TRIM('Student Raw Data'!H3)="Neither Agree nor Disagree"),3,IF(TRIM('Student Raw Data'!H3)="Agree",4,IF(OR(TRIM('Student Raw Data'!H3)="Strongly agree",TRIM('Student Raw Data'!H3)="Strongly Agree"),5,"")))))) -> 3 | I3: =IF('Student Raw Data'!I3="","",IF(OR(TRIM('Student Raw Data'!I3)="Strongly disagree",TRIM('Student Raw Data'!I3)="Strongly Disagree"),1,IF(TRIM('Student Raw Data'!I3)="Disagree",2,IF(OR(TRIM('Student Raw Data'!I3)="Neutral",TRIM('Student Raw Data'!I3)="Neither Agree nor Disagree"),3,IF(TRIM('Student Raw Data'!I3)="Agree",4,IF(OR(TRIM('Student Raw Data'!I3)="Strongly agree",TRIM('Student Raw Data'!I3)="Strongly Agree"),5,"")))))) -> 4 | J3: =IF('Student Raw Data'!J3="","",IF(OR(TRIM('Student Raw Data'!J3)="Strongly disagree",TRIM('Student Raw Data'!J3)="Strongly Disagree"),1,IF(TRIM('Student Raw Data'!J3)="Disagree",2,IF(OR(TRIM('Student Raw Data'!J3)="Neutral",TRIM('Student Raw Data'!J3)="Neither Agree nor Disagree"),3,IF(TRIM('Student Raw Data'!J3)="Agree",4,IF(OR(TRIM('Student Raw Data'!J3)="Strongly agree",TRIM('Student Raw Data'!J3)="Strongly Agree"),5,"")))))) -> 4 | K3: =IF('Student Raw Data'!K3="","",IF(OR(TRIM('Student Raw Data'!K3)="Strongly disagree",TRIM('Student Raw Data'!K3)="Strongly Disagree"),1,IF(TRIM('Student Raw Data'!K3)="Disagree",2,IF(OR(TRIM('Student Raw Data'!K3)="Neutral",TRIM('Student Raw Data'!K3)="Neither Agree nor Disagree"),3,IF(TRIM('Student Raw Data'!K3)="Agree",4,IF(OR(TRIM('Student Raw Data'!K3)="Strongly agree",TRIM('Student Raw Data'!K3)="Strongly Agree"),5,"")))))) -> 3 | L3: =IF('Student Raw Data'!L3="","",IF(OR(TRIM('Student Raw Data'!L3)="Strongly disagree",TRIM('Student Raw Data'!L3)="Strongly Disagree"),1,IF(TRIM('Student Raw Data'!L3)="Disagree",2,IF(OR(TRIM('Student Raw Data'!L3)="Neutral",TRIM('Student Raw Data'!L3)="Neither Agree nor Disagree"),3,IF(TRIM('Student Raw Data'!L3)="Agree",4,IF(OR(TRIM('Student Raw Data'!L3)="Strongly agree",TRIM('Student Raw Data'!L3)="Strongly Agree"),5,"")))))) -> 4 | M3: =IF('Student Raw Data'!M3="","",IF(OR(TRIM('Student Raw Data'!M3)="Strongly disagree",TRIM('Student Raw Data'!M3)="Strongly Disagree"),1,IF(TRIM('Student Raw Data'!M3)="Disagree",2,IF(OR(TRIM('Student Raw Data'!M3)="Neutral",TRIM('Student Raw Data'!M3)="Neither Agree nor Disagree"),3,IF(TRIM('Student Raw Data'!M3)="Agree",4,IF(OR(TRIM('Student Raw Data'!M3)="Strongly agree",TRIM('Student Raw Data'!M3)="Strongly Agree"),5,"")))))) -> 4 | N3: =IF('Student Raw Data'!N3="","",IF(OR(TRIM('Student Raw Data'!N3)="Strongly disagree",TRIM('Student Raw Data'!N3)="Strongly Disagree"),1,IF(TRIM('Student Raw Data'!N3)="Disagree",2,IF(OR(TRIM('Student Raw Data'!N3)="Neutral",TRIM('Student Raw Data'!N3)="Neither Agree nor Disagree"),3,IF(TRIM('Student Raw Data'!N3)="Agree",4,IF(OR(TRIM('Student Raw Data'!N3)="Strongly agree",TRIM('Student Raw Data'!N3)="Strongly Agree"),5,"")))))) -> 4 | ... Z3: =IF('Student Raw Data'!Z3="","",IF(OR(TRIM('Student Raw Data'!Z3)="Strongly disagree",TRIM('Student Raw Data'!Z3)="Strongly Disagree"),1,IF(TRIM('Student Raw Data'!Z3)="Disagree",2,IF(OR(TRIM('Student Raw Data'!Z3)="Neutral",TRIM('Student Raw Data'!Z3)="Neither Agree nor Disagree"),3,IF(TRIM('Student Raw Data'!Z3)="Agree",4,IF(OR(TRIM('Student Raw Data'!Z3)="Strongly agree",TRIM('Student Raw Data'!Z3)="Strongly Agree"),5,"")))))) -> 5 | AA3: ='Student Raw Data'!AA3 -> 4 | AB3: ='Student Raw Data'!AB3 -> Agree | AC3: ='Student Raw Data'!AC3 -> Probably Yes | AD3: ='Student Raw Data'!AD3 -> It gets very crowded during peak hours, and there is often a long wait time to use popular equipment like dumbbells, benches, or cables | AE3: ='Student Raw Data'!AE3 -> Adding a few more sets of popular weights and benches would greatly improve the experience and reduce waiting | AF3: ='Student Raw Data'!AF3 -> Overall, the gym is a great facility, but managing peak-hour traffic or adding a real-time crowd tracker could help.
A4: ='Student Raw Data'!A4 -> 46276.873 | B4: ='Student Raw Data'!B4 -> Yes | C4: ='Student Raw Data'!C4 -> PGDM | D4: ='Student Raw Data'!D4 -> 4-5 times a week | E4: ='Student Raw Data'!E4 -> 1–3 months | F4: ='Student Raw Data'!F4 -> Evening | G4: =IF('Student Raw Data'!G4="","",IF(OR(TRIM('Student Raw Data'!G4)="Strongly disagree",TRIM('Student Raw Data'!G4)="Strongly Disagree"),1,IF(TRIM('Student Raw Data'!G4)="Disagree",2,IF(OR(TRIM('Student Raw Data'!G4)="Neutral",TRIM('Student Raw Data'!G4)="Neither Agree nor Disagree"),3,IF(TRIM('Student Raw Data'!G4)="Agree",4,IF(OR(TRIM('Student Raw Data'!G4)="Strongly agree",TRIM('Student Raw Data'!G4)="Strongly Agree"),5,"")))))) -> 4 | H4: =IF('Student Raw Data'!H4="","",IF(OR(TRIM('Student Raw Data'!H4)="Strongly disagree",TRIM('Student Raw Data'!H4)="Strongly Disagree"),1,IF(TRIM('Student Raw Data'!H4)="Disagree",2,IF(OR(TRIM('Student Raw Data'!H4)="Neutral",TRIM('Student Raw Data'!H4)="Neither Agree nor Disagree"),3,IF(TRIM('Student Raw Data'!H4)="Agree",4,IF(OR(TRIM('Student Raw Data'!H4)="Strongly agree",TRIM('Student Raw Data'!H4)="Strongly Agree"),5,"")))))) -> 3 | I4: =IF('Student Raw Data'!I4="","",IF(OR(TRIM('Student Raw Data'!I4)="Strongly disagree",TRIM('Student Raw Data'!I4)="Strongly Disagree"),1,IF(TRIM('Student Raw Data'!I4)="Disagree",2,IF(OR(TRIM('Student Raw Data'!I4)="Neutral",TRIM('Student Raw Data'!I4)="Neither Agree nor Disagree"),3,IF(TRIM('Student Raw Data'!I4)="Agree",4,IF(OR(TRIM('Student Raw Data'!I4)="Strongly agree",TRIM('Student Raw Data'!I4)="Strongly Agree"),5,"")))))) -> 4 | J4: =IF('Student Raw Data'!J4="","",IF(OR(TRIM('Student Raw Data'!J4)="Strongly disagree",TRIM('Student Raw Data'!J4)="Strongly Disagree"),1,IF(TRIM('Student Raw Data'!J4)="Disagree",2,IF(OR(TRIM('Student Raw Data'!J4)="Neutral",TRIM('Student Raw Data'!J4)="Neither Agree nor Disagree"),3,IF(TRIM('Student Raw Data'!J4)="Agree",4,IF(OR(TRIM('Student Raw Data'!J4)="Strongly agree",TRIM('Student Raw Data'!J4)="Strongly Agree"),5,"")))))) -> 4 | K4: =IF('Student Raw Data'!K4="","",IF(OR(TRIM('Student Raw Data'!K4)="Strongly disagree",TRIM('Student Raw Data'!K4)="Strongly Disagree"),1,IF(TRIM('Student Raw Data'!K4)="Disagree",2,IF(OR(TRIM('Student Raw Data'!K4)="Neutral",TRIM('Student Raw Data'!K4)="Neither Agree nor Disagree"),3,IF(TRIM('Student Raw Data'!K4)="Agree",4,IF(OR(TRIM('Student Raw Data'!K4)="Strongly agree",TRIM('Student Raw Data'!K4)="Strongly Agree"),5,"")))))) -> 3 | L4: =IF('Student Raw Data'!L4="","",IF(OR(TRIM('Student Raw Data'!L4)="Strongly disagree",TRIM('Student Raw Data'!L4)="Strongly Disagree"),1,IF(TRIM('Student Raw Data'!L4)="Disagree",2,IF(OR(TRIM('Student Raw Data'!L4)="Neutral",TRIM('Student Raw Data'!L4)="Neither Agree nor Disagree"),3,IF(TRIM('Student Raw Data'!L4)="Agree",4,IF(OR(TRIM('Student Raw Data'!L4)="Strongly agree",TRIM('Student Raw Data'!L4)="Strongly Agree"),5,"")))))) -> 4 | M4: =IF('Student Raw Data'!M4="","",IF(OR(TRIM('Student Raw Data'!M4)="Strongly disagree",TRIM('Student Raw Data'!M4)="Strongly Disagree"),1,IF(TRIM('Student Raw Data'!M4)="Disagree",2,IF(OR(TRIM('Student Raw Data'!M4)="Neutral",TRIM('Student Raw Data'!M4)="Neither Agree nor Disagree"),3,IF(TRIM('Student Raw Data'!M4)="Agree",4,IF(OR(TRIM('Student Raw Data'!M4)="Strongly agree",TRIM('Student Raw Data'!M4)="Strongly Agree"),5,"")))))) -> 4 | N4: =IF('Student Raw Data'!N4="","",IF(OR(TRIM('Student Raw Data'!N4)="Strongly disagree",TRIM('Student Raw Data'!N4)="Strongly Disagree"),1,IF(TRIM('Student Raw Data'!N4)="Disagree",2,IF(OR(TRIM('Student Raw Data'!N4)="Neutral",TRIM('Student Raw Data'!N4)="Neither Agree nor Disagree"),3,IF(TRIM('Student Raw Data'!N4)="Agree",4,IF(OR(TRIM('Student Raw Data'!N4)="Strongly agree",TRIM('Student Raw Data'!N4)="Strongly Agree"),5,"")))))) -> 5 | ... Z4: =IF('Student Raw Data'!Z4="","",IF(OR(TRIM('Student Raw Data'!Z4)="Strongly disagree",TRIM('Student Raw Data'!Z4)="Strongly Disagree"),1,IF(TRIM('Student Raw Data'!Z4)="Disagree",2,IF(OR(TRIM('Student Raw Data'!Z4)="Neutral",TRIM('Student Raw Data'!Z4)="Neither Agree nor Disagree"),3,IF(TRIM('Student Raw Data'!Z4)="Agree",4,IF(OR(TRIM('Student Raw Data'!Z4)="Strongly agree",TRIM('Student Raw Data'!Z4)="Strongly Agree"),5,"")))))) -> 3 | AA4: ='Student Raw Data'!AA4 -> 5 | AB4: ='Student Raw Data'!AB4 -> Strongly Agree | AC4: ='Student Raw Data'!AC4 -> Definitely Yes | AD4: ='Student Raw Data'!AD4 -> 0 | AE4: ='Student Raw Data'!AE4 -> 0 | AF4: ='Student Raw Data'!AF4 -> 0
A5: ='Student Raw Data'!A5 -> 46277.024 | B5: ='Student Raw Data'!B5 -> Yes | C5: ='Student Raw Data'!C5 -> PGDM | D5: ='Student Raw Data'!D5 -> 4-5 times a week | E5: ='Student Raw Data'!E5 -> 1–3 months | F5: ='Student Raw Data'!F5 -> Evening | G5: =IF('Student Raw Data'!G5="","",IF(OR(TRIM('Student Raw Data'!G5)="Strongly disagree",TRIM('Student Raw Data'!G5)="Strongly Disagree"),1,IF(TRIM('Student Raw Data'!G5)="Disagree",2,IF(OR(TRIM('Student Raw Data'!G5)="Neutral",TRIM('Student Raw Data'!G5)="Neither Agree nor Disagree"),3,IF(TRIM('Student Raw Data'!G5)="Agree",4,IF(OR(TRIM('Student Raw Data'!G5)="Strongly agree",TRIM('Student Raw Data'!G5)="Strongly Agree"),5,"")))))) -> 5 | H5: =IF('Student Raw Data'!H5="","",IF(OR(TRIM('Student Raw Data'!H5)="Strongly disagree",TRIM('Student Raw Data'!H5)="Strongly Disagree"),1,IF(TRIM('Student Raw Data'!H5)="Disagree",2,IF(OR(TRIM('Student Raw Data'!H5)="Neutral",TRIM('Student Raw Data'!H5)="Neither Agree nor Disagree"),3,IF(TRIM('Student Raw Data'!H5)="Agree",4,IF(OR(TRIM('Student Raw Data'!H5)="Strongly agree",TRIM('Student Raw Data'!H5)="Strongly Agree"),5,"")))))) -> 5 | I5: =IF('Student Raw Data'!I5="","",IF(OR(TRIM('Student Raw Data'!I5)="Strongly disagree",TRIM('Student Raw Data'!I5)="Strongly Disagree"),1,IF(TRIM('Student Raw Data'!I5)="Disagree",2,IF(OR(TRIM('Student Raw Data'!I5)="Neutral",TRIM('Student Raw Data'!I5)="Neither Agree nor Disagree"),3,IF(TRIM('Student Raw Data'!I5)="Agree",4,IF(OR(TRIM('Student Raw Data'!I5)="Strongly agree",TRIM('Student Raw Data'!I5)="Strongly Agree"),5,"")))))) -> 5 | J5: =IF('Student Raw Data'!J5="","",IF(OR(TRIM('Student Raw Data'!J5)="Strongly disagree",TRIM('Student Raw Data'!J5)="Strongly Disagree"),1,IF(TRIM('Student Raw Data'!J5)="Disagree",2,IF(OR(TRIM('Student Raw Data'!J5)="Neutral",TRIM('Student Raw Data'!J5)="Neither Agree nor Disagree"),3,IF(TRIM('Student Raw Data'!J5)="Agree",4,IF(OR(TRIM('Student Raw Data'!J5)="Strongly agree",TRIM('Student Raw Data'!J5)="Strongly Agree"),5,"")))))) -> 5 | K5: =IF('Student Raw Data'!K5="","",IF(OR(TRIM('Student Raw Data'!K5)="Strongly disagree",TRIM('Student Raw Data'!K5)="Strongly Disagree"),1,IF(TRIM('Student Raw Data'!K5)="Disagree",2,IF(OR(TRIM('Student Raw Data'!K5)="Neutral",TRIM('Student Raw Data'!K5)="Neither Agree nor Disagree"),3,IF(TRIM('Student Raw Data'!K5)="Agree",4,IF(OR(TRIM('Student Raw Data'!K5)="Strongly agree",TRIM('Student Raw Data'!K5)="Strongly Agree"),5,"")))))) -> 5 | L5: =IF('Student Raw Data'!L5="","",IF(OR(TRIM('Student Raw Data'!L5)="Strongly disagree",TRIM('Student Raw Data'!L5)="Strongly Disagree"),1,IF(TRIM('Student Raw Data'!L5)="Disagree",2,IF(OR(TRIM('Student Raw Data'!L5)="Neutral",TRIM('Student Raw Data'!L5)="Neither Agree nor Disagree"),3,IF(TRIM('Student Raw Data'!L5)="Agree",4,IF(OR(TRIM('Student Raw Data'!L5)="Strongly agree",TRIM('Student Raw Data'!L5)="Strongly Agree"),5,"")))))) -> 5 | M5: =IF('Student Raw Data'!M5="","",IF(OR(TRIM('Student Raw Data'!M5)="Strongly disagree",TRIM('Student Raw Data'!M5)="Strongly Disagree"),1,IF(TRIM('Student Raw Data'!M5)="Disagree",2,IF(OR(TRIM('Student Raw Data'!M5)="Neutral",TRIM('Student Raw Data'!M5)="Neither Agree nor Disagree"),3,IF(TRIM('Student Raw Data'!M5)="Agree",4,IF(OR(TRIM('Student Raw Data'!M5)="Strongly agree",TRIM('Student Raw Data'!M5)="Strongly Agree"),5,"")))))) -> 5 | N5: =IF('Student Raw Data'!N5="","",IF(OR(TRIM('Student Raw Data'!N5)="Strongly disagree",TRIM('Student Raw Data'!N5)="Strongly Disagree"),1,IF(TRIM('Student Raw Data'!N5)="Disagree",2,IF(OR(TRIM('Student Raw Data'!N5)="Neutral",TRIM('Student Raw Data'!N5)="Neither Agree nor Disagree"),3,IF(TRIM('Student Raw Data'!N5)="Agree",4,IF(OR(TRIM('Student Raw Data'!N5)="Strongly agree",TRIM('Student Raw Data'!N5)="Strongly Agree"),5,"")))))) -> 5 | ... Z5: =IF('Student Raw Data'!Z5="","",IF(OR(TRIM('Student Raw Data'!Z5)="Strongly disagree",TRIM('Student Raw Data'!Z5)="Strongly Disagree"),1,IF(TRIM('Student Raw Data'!Z5)="Disagree",2,IF(OR(TRIM('Student Raw Data'!Z5)="Neutral",TRIM('Student Raw Data'!Z5)="Neither Agree nor Disagree"),3,IF(TRIM('Student Raw Data'!Z5)="Agree",4,IF(OR(TRIM('Student Raw Data'!Z5)="Strongly agree",TRIM('Student Raw Data'!Z5)="Strongly Agree"),5,"")))))) -> 5 | AA5: ='Student Raw Data'!AA5 -> 5 | AB5: ='Student Raw Data'!AB5 -> Strongly Agree | AC5: ='Student Raw Data'!AC5 -> Definitely Yes | AD5: ='Student Raw Data'!AD5 -> Na | AE5: ='Student Raw Data'!AE5 -> Na | AF5: ='Student Raw Data'!AF5 -> na
A6: ='Student Raw Data'!A6 -> 46277.085 | B6: ='Student Raw Data'!B6 -> Yes | C6: ='Student Raw Data'!C6 -> PGDM | D6: ='Student Raw Data'!D6 -> Daily | E6: ='Student Raw Data'!E6 -> 1–3 months | F6: ='Student Raw Data'!F6 -> Evening | G6: =IF('Student Raw Data'!G6="","",IF(OR(TRIM('Student Raw Data'!G6)="Strongly disagree",TRIM('Student Raw Data'!G6)="Strongly Disagree"),1,IF(TRIM('Student Raw Data'!G6)="Disagree",2,IF(OR(TRIM('Student Raw Data'!G6)="Neutral",TRIM('Student Raw Data'!G6)="Neither Agree nor Disagree"),3,IF(TRIM('Student Raw Data'!G6)="Agree",4,IF(OR(TRIM('Student Raw Data'!G6)="Strongly agree",TRIM('Student Raw Data'!G6)="Strongly Agree"),5,"")))))) -> 3 | H6: =IF('Student Raw Data'!H6="","",IF(OR(TRIM('Student Raw Data'!H6)="Strongly disagree",TRIM('Student Raw Data'!H6)="Strongly Disagree"),1,IF(TRIM('Student Raw Data'!H6)="Disagree",2,IF(OR(TRIM('Student Raw Data'!H6)="Neutral",TRIM('Student Raw Data'!H6)="Neither Agree nor Disagree"),3,IF(TRIM('Student Raw Data'!H6)="Agree",4,IF(OR(TRIM('Student Raw Data'!H6)="Strongly agree",TRIM('Student Raw Data'!H6)="Strongly Agree"),5,"")))))) -> 5 | I6: =IF('Student Raw Data'!I6="","",IF(OR(TRIM('Student Raw Data'!I6)="Strongly disagree",TRIM('Student Raw Data'!I6)="Strongly Disagree"),1,IF(TRIM('Student Raw Data'!I6)="Disagree",2,IF(OR(TRIM('Student Raw Data'!I6)="Neutral",TRIM('Student Raw Data'!I6)="Neither Agree nor Disagree"),3,IF(TRIM('Student Raw Data'!I6)="Agree",4,IF(OR(TRIM('Student Raw Data'!I6)="Strongly agree",TRIM('Student Raw Data'!I6)="Strongly Agree"),5,"")))))) -> 5 | J6: =IF('Student Raw Data'!J6="","",IF(OR(TRIM('Student Raw Data'!J6)="Strongly disagree",TRIM('Student Raw Data'!J6)="Strongly Disagree"),1,IF(TRIM('Student Raw Data'!J6)="Disagree",2,IF(OR(TRIM('Student Raw Data'!J6)="Neutral",TRIM('Student Raw Data'!J6)="Neither Agree nor Disagree"),3,IF(TRIM('Student Raw Data'!J6)="Agree",4,IF(OR(TRIM('Student Raw Data'!J6)="Strongly agree",TRIM('Student Raw Data'!J6)="Strongly Agree"),5,"")))))) -> 5 | K6: =IF('Student Raw Data'!K6="","",IF(OR(TRIM('Student Raw Data'!K6)="Strongly disagree",TRIM('Student Raw Data'!K6)="Strongly Disagree"),1,IF(TRIM('Student Raw Data'!K6)="Disagree",2,IF(OR(TRIM('Student Raw Data'!K6)="Neutral",TRIM('Student Raw Data'!K6)="Neither Agree nor Disagree"),3,IF(TRIM('Student Raw Data'!K6)="Agree",4,IF(OR(TRIM('Student Raw Data'!K6)="Strongly agree",TRIM('Student Raw Data'!K6)="Strongly Agree"),5,"")))))) -> 3 | L6: =IF('Student Raw Data'!L6="","",IF(OR(TRIM('Student Raw Data'!L6)="Strongly disagree",TRIM('Student Raw Data'!L6)="Strongly Disagree"),1,IF(TRIM('Student Raw Data'!L6)="Disagree",2,IF(OR(TRIM('Student Raw Data'!L6)="Neutral",TRIM('Student Raw Data'!L6)="Neither Agree nor Disagree"),3,IF(TRIM('Student Raw Data'!L6)="Agree",4,IF(OR(TRIM('Student Raw Data'!L6)="Strongly agree",TRIM('Student Raw Data'!L6)="Strongly Agree"),5,"")))))) -> 3 | M6: =IF('Student Raw Data'!M6="","",IF(OR(TRIM('Student Raw Data'!M6)="Strongly disagree",TRIM('Student Raw Data'!M6)="Strongly Disagree"),1,IF(TRIM('Student Raw Data'!M6)="Disagree",2,IF(OR(TRIM('Student Raw Data'!M6)="Neutral",TRIM('Student Raw Data'!M6)="Neither Agree nor Disagree"),3,IF(TRIM('Student Raw Data'!M6)="Agree",4,IF(OR(TRIM('Student Raw Data'!M6)="Strongly agree",TRIM('Student Raw Data'!M6)="Strongly Agree"),5,"")))))) -> 5 | N6: =IF('Student Raw Data'!N6="","",IF(OR(TRIM('Student Raw Data'!N6)="Strongly disagree",TRIM('Student Raw Data'!N6)="Strongly Disagree"),1,IF(TRIM('Student Raw Data'!N6)="Disagree",2,IF(OR(TRIM('Student Raw Data'!N6)="Neutral",TRIM('Student Raw Data'!N6)="Neither Agree nor Disagree"),3,IF(TRIM('Student Raw Data'!N6)="Agree",4,IF(OR(TRIM('Student Raw Data'!N6)="Strongly agree",TRIM('Student Raw Data'!N6)="Strongly Agree"),5,"")))))) -> 5 | ... Z6: =IF('Student Raw Data'!Z6="","",IF(OR(TRIM('Student Raw Data'!Z6)="Strongly disagree",TRIM('Student Raw Data'!Z6)="Strongly Disagree"),1,IF(TRIM('Student Raw Data'!Z6)="Disagree",2,IF(OR(TRIM('Student Raw Data'!Z6)="Neutral",TRIM('Student Raw Data'!Z6)="Neither Agree nor Disagree"),3,IF(TRIM('Student Raw Data'!Z6)="Agree",4,IF(OR(TRIM('Student Raw Data'!Z6)="Strongly agree",TRIM('Student Raw Data'!Z6)="Strongly Agree"),5,"")))))) -> 5 | AA6: ='Student Raw Data'!AA6 -> 3 | AB6: ='Student Raw Data'!AB6 -> Agree | AC6: ='Student Raw Data'!AC6 -> Probably Yes | AD6: ='Student Raw Data'!AD6 -> machine is not working like treadmill. | AE6: ='Student Raw Data'!AE6 -> Repair treadmill or Replace to new. | AF6: ='Student Raw Data'!AF6 -> add more equipment.
A7: ='Student Raw Data'!A7 -> 46277.086 | B7: ='Student Raw Data'!B7 -> Yes | C7: ='Student Raw Data'!C7 -> PGDM | D7: ='Student Raw Data'!D7 -> 2-3 times a week | E7: ='Student Raw Data'!E7 -> 1–3 months | F7: ='Student Raw Data'!F7 -> Evening | G7: =IF('Student Raw Data'!G7="","",IF(OR(TRIM('Student Raw Data'!G7)="Strongly disagree",TRIM('Student Raw Data'!G7)="Strongly Disagree"),1,IF(TRIM('Student Raw Data'!G7)="Disagree",2,IF(OR(TRIM('Student Raw Data'!G7)="Neutral",TRIM('Student Raw Data'!G7)="Neither Agree nor Disagree"),3,IF(TRIM('Student Raw Data'!G7)="Agree",4,IF(OR(TRIM('Student Raw Data'!G7)="Strongly agree",TRIM('Student Raw Data'!G7)="Strongly Agree"),5,"")))))) -> 4 | H7: =IF('Student Raw Data'!H7="","",IF(OR(TRIM('Student Raw Data'!H7)="Strongly disagree",TRIM('Student Raw Data'!H7)="Strongly Disagree"),1,IF(TRIM('Student Raw Data'!H7)="Disagree",2,IF(OR(TRIM('Student Raw Data'!H7)="Neutral",TRIM('Student Raw Data'!H7)="Neither Agree nor Disagree"),3,IF(TRIM('Student Raw Data'!H7)="Agree",4,IF(OR(TRIM('Student Raw Data'!H7)="Strongly agree",TRIM('Student Raw Data'!H7)="Strongly Agree"),5,"")))))) -> 4 | I7: =IF('Student Raw Data'!I7="","",IF(OR(TRIM('Student Raw Data'!I7)="Strongly disagree",TRIM('Student Raw Data'!I7)="Strongly Disagree"),1,IF(TRIM('Student Raw Data'!I7)="Disagree",2,IF(OR(TRIM('Student Raw Data'!I7)="Neutral",TRIM('Student Raw Data'!I7)="Neither Agree nor Disagree"),3,IF(TRIM('Student Raw Data'!I7)="Agree",4,IF(OR(TRIM('Student Raw Data'!I7)="Strongly agree",TRIM('Student Raw Data'!I7)="Strongly Agree"),5,"")))))) -> 5 | J7: =IF('Student Raw Data'!J7="","",IF(OR(TRIM('Student Raw Data'!J7)="Strongly disagree",TRIM('Student Raw Data'!J7)="Strongly Disagree"),1,IF(TRIM('Student Raw Data'!J7)="Disagree",2,IF(OR(TRIM('Student Raw Data'!J7)="Neutral",TRIM('Student Raw Data'!J7)="Neither Agree nor Disagree"),3,IF(TRIM('Student Raw Data'!J7)="Agree",4,IF(OR(TRIM('Student Raw Data'!J7)="Strongly agree",TRIM('Student Raw Data'!J7)="Strongly Agree"),5,"")))))) -> 5 | K7: =IF('Student Raw Data'!K7="","",IF(OR(TRIM('Student Raw Data'!K7)="Strongly disagree",TRIM('Student Raw Data'!K7)="Strongly Disagree"),1,IF(TRIM('Student Raw Data'!K7)="Disagree",2,IF(OR(TRIM('Student Raw Data'!K7)="Neutral",TRIM('Student Raw Data'!K7)="Neither Agree nor Disagree"),3,IF(TRIM('Student Raw Data'!K7)="Agree",4,IF(OR(TRIM('Student Raw Data'!K7)="Strongly agree",TRIM('Student Raw Data'!K7)="Strongly Agree"),5,"")))))) -> 1 | L7: =IF('Student Raw Data'!L7="","",IF(OR(TRIM('Student Raw Data'!L7)="Strongly disagree",TRIM('Student Raw Data'!L7)="Strongly Disagree"),1,IF(TRIM('Student Raw Data'!L7)="Disagree",2,IF(OR(TRIM('Student Raw Data'!L7)="Neutral",TRIM('Student Raw Data'!L7)="Neither Agree nor Disagree"),3,IF(TRIM('Student Raw Data'!L7)="Agree",4,IF(OR(TRIM('Student Raw Data'!L7)="Strongly agree",TRIM('Student Raw Data'!L7)="Strongly Agree"),5,"")))))) -> 5 | M7: =IF('Student Raw Data'!M7="","",IF(OR(TRIM('Student Raw Data'!M7)="Strongly disagree",TRIM('Student Raw Data'!M7)="Strongly Disagree"),1,IF(TRIM('Student Raw Data'!M7)="Disagree",2,IF(OR(TRIM('Student Raw Data'!M7)="Neutral",TRIM('Student Raw Data'!M7)="Neither Agree nor Disagree"),3,IF(TRIM('Student Raw Data'!M7)="Agree",4,IF(OR(TRIM('Student Raw Data'!M7)="Strongly agree",TRIM('Student Raw Data'!M7)="Strongly Agree"),5,"")))))) -> 4 | N7: =IF('Student Raw Data'!N7="","",IF(OR(TRIM('Student Raw Data'!N7)="Strongly disagree",TRIM('Student Raw Data'!N7)="Strongly Disagree"),1,IF(TRIM('Student Raw Data'!N7)="Disagree",2,IF(OR(TRIM('Student Raw Data'!N7)="Neutral",TRIM('Student Raw Data'!N7)="Neither Agree nor Disagree"),3,IF(TRIM('Student Raw Data'!N7)="Agree",4,IF(OR(TRIM('Student Raw Data'!N7)="Strongly agree",TRIM('Student Raw Data'!N7)="Strongly Agree"),5,"")))))) -> 5 | ... Z7: =IF('Student Raw Data'!Z7="","",IF(OR(TRIM('Student Raw Data'!Z7)="Strongly disagree",TRIM('Student Raw Data'!Z7)="Strongly Disagree"),1,IF(TRIM('Student Raw Data'!Z7)="Disagree",2,IF(OR(TRIM('Student Raw Data'!Z7)="Neutral",TRIM('Student Raw Data'!Z7)="Neither Agree nor Disagree"),3,IF(TRIM('Student Raw Data'!Z7)="Agree",4,IF(OR(TRIM('Student Raw Data'!Z7)="Strongly agree",TRIM('Student Raw Data'!Z7)="Strongly Agree"),5,"")))))) -> 4 | AA7: ='Student Raw Data'!AA7 -> 4 | AB7: ='Student Raw Data'!AB7 -> Agree | AC7: ='Student Raw Data'!AC7 -> Probably Yes | AD7: ='Student Raw Data'!AD7 -> Less machines variety at the gym | AE7: ='Student Raw Data'!AE7 -> Install new machines for better experience | AF7: ='Student Raw Data'!AF7 -> There should be more exercise machines
A8: ='Student Raw Data'!A8 -> 46277.345 | B8: ='Student Raw Data'!B8 -> Yes | C8: ='Student Raw Data'!C8 -> PGDM-FM | D8: ='Student Raw Data'!D8 -> Daily | E8: ='Student Raw Data'!E8 -> 3–6 months | F8: ='Student Raw Data'!F8 -> No specific preference | G8: =IF('Student Raw Data'!G8="","",IF(OR(TRIM('Student Raw Data'!G8)="Strongly disagree",TRIM('Student Raw Data'!G8)="Strongly Disagree"),1,IF(TRIM('Student Raw Data'!G8)="Disagree",2,IF(OR(TRIM('Student Raw Data'!G8)="Neutral",TRIM('Student Raw Data'!G8)="Neither Agree nor Disagree"),3,IF(TRIM('Student Raw Data'!G8)="Agree",4,IF(OR(TRIM('Student Raw Data'!G8)="Strongly agree",TRIM('Student Raw Data'!G8)="Strongly Agree"),5,"")))))) -> 4 | H8: =IF('Student Raw Data'!H8="","",IF(OR(TRIM('Student Raw Data'!H8)="Strongly disagree",TRIM('Student Raw Data'!H8)="Strongly Disagree"),1,IF(TRIM('Student Raw Data'!H8)="Disagree",2,IF(OR(TRIM('Student Raw Data'!H8)="Neutral",TRIM('Student Raw Data'!H8)="Neither Agree nor Disagree"),3,IF(TRIM('Student Raw Data'!H8)="Agree",4,IF(OR(TRIM('Student Raw Data'!H8)="Strongly agree",TRIM('Student Raw Data'!H8)="Strongly Agree"),5,"")))))) -> 4 | I8: =IF('Student Raw Data'!I8="","",IF(OR(TRIM('Student Raw Data'!I8)="Strongly disagree",TRIM('Student Raw Data'!I8)="Strongly Disagree"),1,IF(TRIM('Student Raw Data'!I8)="Disagree",2,IF(OR(TRIM('Student Raw Data'!I8)="Neutral",TRIM('Student Raw Data'!I8)="Neither Agree nor Disagree"),3,IF(TRIM('Student Raw Data'!I8)="Agree",4,IF(OR(TRIM('Student Raw Data'!I8)="Strongly agree",TRIM('Student Raw Data'!I8)="Strongly Agree"),5,"")))))) -> 5 | J8: =IF('Student Raw Data'!J8="","",IF(OR(TRIM('Student Raw Data'!J8)="Strongly disagree",TRIM('Student Raw Data'!J8)="Strongly Disagree"),1,IF(TRIM('Student Raw Data'!J8)="Disagree",2,IF(OR(TRIM('Student Raw Data'!J8)="Neutral",TRIM('Student Raw Data'!J8)="Neither Agree nor Disagree"),3,IF(TRIM('Student Raw Data'!J8)="Agree",4,IF(OR(TRIM('Student Raw Data'!J8)="Strongly agree",TRIM('Student Raw Data'!J8)="Strongly Agree"),5,"")))))) -> 5 | K8: =IF('Student Raw Data'!K8="","",IF(OR(TRIM('Student Raw Data'!K8)="Strongly disagree",TRIM('Student Raw Data'!K8)="Strongly Disagree"),1,IF(TRIM('Student Raw Data'!K8)="Disagree",2,IF(OR(TRIM('Student Raw Data'!K8)="Neutral",TRIM('Student Raw Data'!K8)="Neither Agree nor Disagree"),3,IF(TRIM('Student Raw Data'!K8)="Agree",4,IF(OR(TRIM('Student Raw Data'!K8)="Strongly agree",TRIM('Student Raw Data'!K8)="Strongly Agree"),5,"")))))) -> 4 | L8: =IF('Student Raw Data'!L8="","",IF(OR(TRIM('Student Raw Data'!L8)="Strongly disagree",TRIM('Student Raw Data'!L8)="Strongly Disagree"),1,IF(TRIM('Student Raw Data'!L8)="Disagree",2,IF(OR(TRIM('Student Raw Data'!L8)="Neutral",TRIM('Student Raw Data'!L8)="Neither Agree nor Disagree"),3,IF(TRIM('Student Raw Data'!L8)="Agree",4,IF(OR(TRIM('Student Raw Data'!L8)="Strongly agree",TRIM('Student Raw Data'!L8)="Strongly Agree"),5,"")))))) -> 4 | M8: =IF('Student Raw Data'!M8="","",IF(OR(TRIM('Student Raw Data'!M8)="Strongly disagree",TRIM('Student Raw Data'!M8)="Strongly Disagree"),1,IF(TRIM('Student Raw Data'!M8)="Disagree",2,IF(OR(TRIM('Student Raw Data'!M8)="Neutral",TRIM('Student Raw Data'!M8)="Neither Agree nor Disagree"),3,IF(TRIM('Student Raw Data'!M8)="Agree",4,IF(OR(TRIM('Student Raw Data'!M8)="Strongly agree",TRIM('Student Raw Data'!M8)="Strongly Agree"),5,"")))))) -> 5 | N8: =IF('Student Raw Data'!N8="","",IF(OR(TRIM('Student Raw Data'!N8)="Strongly disagree",TRIM('Student Raw Data'!N8)="Strongly Disagree"),1,IF(TRIM('Student Raw Data'!N8)="Disagree",2,IF(OR(TRIM('Student Raw Data'!N8)="Neutral",TRIM('Student Raw Data'!N8)="Neither Agree nor Disagree"),3,IF(TRIM('Student Raw Data'!N8)="Agree",4,IF(OR(TRIM('Student Raw Data'!N8)="Strongly agree",TRIM('Student Raw Data'!N8)="Strongly Agree"),5,"")))))) -> 2 | ... Z8: =IF('Student Raw Data'!Z8="","",IF(OR(TRIM('Student Raw Data'!Z8)="Strongly disagree",TRIM('Student Raw Data'!Z8)="Strongly Disagree"),1,IF(TRIM('Student Raw Data'!Z8)="Disagree",2,IF(OR(TRIM('Student Raw Data'!Z8)="Neutral",TRIM('Student Raw Data'!Z8)="Neither Agree nor Disagree"),3,IF(TRIM('Student Raw Data'!Z8)="Agree",4,IF(OR(TRIM('Student Raw Data'!Z8)="Strongly agree",TRIM('Student Raw Data'!Z8)="Strongly Agree"),5,"")))))) -> 5 | AA8: ='Student Raw Data'!AA8 -> 5 | AB8: ='Student Raw Data'!AB8 -> Strongly Agree | AC8: ='Student Raw Data'!AC8 -> Definitely Yes | AD8: ='Student Raw Data'!AD8 -> 0 | AE8: ='Student Raw Data'!AE8 -> Please change few machines that are just taking space. | AF8: ='Student Raw Data'!AF8 -> 0
A9: ='Student Raw Data'!A9 -> 46277.39 | B9: ='Student Raw Data'!B9 -> Yes | C9: ='Student Raw Data'!C9 -> PGDM | D9: ='Student Raw Data'!D9 -> Daily | E9: ='Student Raw Data'!E9 -> More than 1 year | F9: ='Student Raw Data'!F9 -> Evening | G9: =IF('Student Raw Data'!G9="","",IF(OR(TRIM('Student Raw Data'!G9)="Strongly disagree",TRIM('Student Raw Data'!G9)="Strongly Disagree"),1,IF(TRIM('Student Raw Data'!G9)="Disagree",2,IF(OR(TRIM('Student Raw Data'!G9)="Neutral",TRIM('Student Raw Data'!G9)="Neither Agree nor Disagree"),3,IF(TRIM('Student Raw Data'!G9)="Agree",4,IF(OR(TRIM('Student Raw Data'!G9)="Strongly agree",TRIM('Student Raw Data'!G9)="Strongly Agree"),5,"")))))) -> 4 | H9: =IF('Student Raw Data'!H9="","",IF(OR(TRIM('Student Raw Data'!H9)="Strongly disagree",TRIM('Student Raw Data'!H9)="Strongly Disagree"),1,IF(TRIM('Student Raw Data'!H9)="Disagree",2,IF(OR(TRIM('Student Raw Data'!H9)="Neutral",TRIM('Student Raw Data'!H9)="Neither Agree nor Disagree"),3,IF(TRIM('Student Raw Data'!H9)="Agree",4,IF(OR(TRIM('Student Raw Data'!H9)="Strongly agree",TRIM('Student Raw Data'!H9)="Strongly Agree"),5,"")))))) -> 1 | I9: =IF('Student Raw Data'!I9="","",IF(OR(TRIM('Student Raw Data'!I9)="Strongly disagree",TRIM('Student Raw Data'!I9)="Strongly Disagree"),1,IF(TRIM('Student Raw Data'!I9)="Disagree",2,IF(OR(TRIM('Student Raw Data'!I9)="Neutral",TRIM('Student Raw Data'!I9)="Neither Agree nor Disagree"),3,IF(TRIM('Student Raw Data'!I9)="Agree",4,IF(OR(TRIM('Student Raw Data'!I9)="Strongly agree",TRIM('Student Raw Data'!I9)="Strongly Agree"),5,"")))))) -> 5 | J9: =IF('Student Raw Data'!J9="","",IF(OR(TRIM('Student Raw Data'!J9)="Strongly disagree",TRIM('Student Raw Data'!J9)="Strongly Disagree"),1,IF(TRIM('Student Raw Data'!J9)="Disagree",2,IF(OR(TRIM('Student Raw Data'!J9)="Neutral",TRIM('Student Raw Data'!J9)="Neither Agree nor Disagree"),3,IF(TRIM('Student Raw Data'!J9)="Agree",4,IF(OR(TRIM('Student Raw Data'!J9)="Strongly agree",TRIM('Student Raw Data'!J9)="Strongly Agree"),5,"")))))) -> 5 | K9: =IF('Student Raw Data'!K9="","",IF(OR(TRIM('Student Raw Data'!K9)="Strongly disagree",TRIM('Student Raw Data'!K9)="Strongly Disagree"),1,IF(TRIM('Student Raw Data'!K9)="Disagree",2,IF(OR(TRIM('Student Raw Data'!K9)="Neutral",TRIM('Student Raw Data'!K9)="Neither Agree nor Disagree"),3,IF(TRIM('Student Raw Data'!K9)="Agree",4,IF(OR(TRIM('Student Raw Data'!K9)="Strongly agree",TRIM('Student Raw Data'!K9)="Strongly Agree"),5,"")))))) -> 4 | L9: =IF('Student Raw Data'!L9="","",IF(OR(TRIM('Student Raw Data'!L9)="Strongly disagree",TRIM('Student Raw Data'!L9)="Strongly Disagree"),1,IF(TRIM('Student Raw Data'!L9)="Disagree",2,IF(OR(TRIM('Student Raw Data'!L9)="Neutral",TRIM('Student Raw Data'!L9)="Neither Agree nor Disagree"),3,IF(TRIM('Student Raw Data'!L9)="Agree",4,IF(OR(TRIM('Student Raw Data'!L9)="Strongly agree",TRIM('Student Raw Data'!L9)="Strongly Agree"),5,"")))))) -> 5 | M9: =IF('Student Raw Data'!M9="","",IF(OR(TRIM('Student Raw Data'!M9)="Strongly disagree",TRIM('Student Raw Data'!M9)="Strongly Disagree"),1,IF(TRIM('Student Raw Data'!M9)="Disagree",2,IF(OR(TRIM('Student Raw Data'!M9)="Neutral",TRIM('Student Raw Data'!M9)="Neither Agree nor Disagree"),3,IF(TRIM('Student Raw Data'!M9)="Agree",4,IF(OR(TRIM('Student Raw Data'!M9)="Strongly agree",TRIM('Student Raw Data'!M9)="Strongly Agree"),5,"")))))) -> 5 | N9: =IF('Student Raw Data'!N9="","",IF(OR(TRIM('Student Raw Data'!N9)="Strongly disagree",TRIM('Student Raw Data'!N9)="Strongly Disagree"),1,IF(TRIM('Student Raw Data'!N9)="Disagree",2,IF(OR(TRIM('Student Raw Data'!N9)="Neutral",TRIM('Student Raw Data'!N9)="Neither Agree nor Disagree"),3,IF(TRIM('Student Raw Data'!N9)="Agree",4,IF(OR(TRIM('Student Raw Data'!N9)="Strongly agree",TRIM('Student Raw Data'!N9)="Strongly Agree"),5,"")))))) -> 5 | ... Z9: =IF('Student Raw Data'!Z9="","",IF(OR(TRIM('Student Raw Data'!Z9)="Strongly disagree",TRIM('Student Raw Data'!Z9)="Strongly Disagree"),1,IF(TRIM('Student Raw Data'!Z9)="Disagree",2,IF(OR(TRIM('Student Raw Data'!Z9)="Neutral",TRIM('Student Raw Data'!Z9)="Neither Agree nor Disagree"),3,IF(TRIM('Student Raw Data'!Z9)="Agree",4,IF(OR(TRIM('Student Raw Data'!Z9)="Strongly agree",TRIM('Student Raw Data'!Z9)="Strongly Agree"),5,"")))))) -> 5 | AA9: ='Student Raw Data'!AA9 -> 5 | AB9: ='Student Raw Data'!AB9 -> Agree | AC9: ='Student Raw Data'!AC9 -> Definitely Yes | AD9: ='Student Raw Data'!AD9 -> Very small as compared to other commercial gyms | AE9: ='Student Raw Data'!AE9 -> Add more machines | AF9: ='Student Raw Data'!AF9 -> 0
